---
order: 128
timestamp: 6/13/2021
topic: programming
deck: Javascript Questions by Lydia Hallie
contentSource: https://github.com/lydiahallie/javascript-questions
title: What's the output?
answer: C
---

  

```javascript
const myPromise = Promise.resolve('Woah some cool data');

(async () => {
  try {
    console.log(await myPromise);
  } catch {
    throw new Error(`Oops didn't work`);
  } finally {
    console.log('Oh finally!');
  }
})();
```


<label for="option-A">A </label>
<span class="option-container">
  <input
    type="radio"
    name="answer-option"
    id="option-A" value="A"
  />
  `Woah some cool data`
</span>
    

<label for="option-B">B </label>
<span class="option-container">
  <input
    type="radio"
    name="answer-option"
    id="option-B" value="B"
  />
  `Oh finally!`
</span>
    

<label for="option-C">C </label>
<span class="option-container">
  <input
    type="radio"
    name="answer-option"
    id="option-C" value="C"
  />
  `Woah some cool data` `Oh finally!`
</span>
    

<label for="option-D">D </label>
<span class="option-container">
  <input
    type="radio"
    name="answer-option"
    id="option-D" value="D"
  />
  `Oops didn't work` `Oh finally!`
</span>
    




SPLIT_MARKER

In the `try` block, we're logging the awaited value of the `myPromise` variable: `"Woah some cool data"`. Since no errors were thrown in the `try` block, the code in the `catch` block doesn't run. The code in the `finally` block _always_ runs, `"Oh finally!"` gets logged.



